<mujoco model="teststand">
  <compiler angle="radian" autolimits="true" meshdir="meshes"/>
  <size/>
  <default/>
  <asset>
    <mesh name="solo_upper_leg_left_side" file="solo_upper_leg_left_side.stl"/>
    <mesh name="solo_lower_leg_left_side" file="solo_lower_leg_left_side.stl"/>
    <mesh name="solo_foot" file="solo_foot.stl"/>
  </asset>
  <worldbody>
    <body name="base_link" pos="0 0 0">
      <inertial pos="0 0 0.05" quat="0.5 0.5 0.5 0.5" mass="0.485" diaginertia="0.00202083 0.00202083 0.000808333"/>
      <joint name="joint_z" pos="0 0 0" axis="0 0 1" type="slide" range="-10 10"/>
      <geom size="0.1 0.05 0.05" type="box" rgba="1 1 1 1"/>
      <body name="upperleg" pos="0 0 0">
        <inertial pos="1.377e-05 0.0193585 -0.078707" quat="0.705834 0.0424071 -0.0424071 0.705834" mass="0.148538" diaginertia="0.000417563 0.00041107 2.46069e-05"/>
        <joint name="HFE" pos="0 0 0" axis="0 1 0" range="-10 10"/>
        <geom type="mesh" rgba="0.8 0.8 0.8 1" mesh="solo_upper_leg_left_side"/>
        <body name="shank" pos="0 0.03745 -0.16">
          <inertial pos="0 0.00789921 -0.102249" quat="0.707067 0.00747737 -0.00747737 0.707067" mass="0.0376361" diaginertia="0.000149205 0.000148819 2.62453e-06"/>
          <joint name="KFE" pos="0 0 0" axis="0 1 0" range="-10 10"/>
          <geom type="mesh" rgba="0.8 0.8 0.8 1" mesh="solo_lower_leg_left_side"/>
          <geom pos="0 0.008 -0.16" type="mesh" rgba="0.8 0.8 0.8 1" mesh="solo_foot"/>
        </body>
      </body>
    </body>
  </worldbody>

  <actuator>
      <motor name="joint_z"       gear="1"  joint="joint_z"/>
      <motor name="HFE"       gear="1"  joint="HFE"/>
      <motor name="KFE"       gear="1"  joint="KFE"/>
    </actuator>
</mujoco>
