<?xml version="1.0" ?>
<robot name="cube">
  <link name="px_link">
    <inertial>
        <origin rpy="0 0 0" xyz="0 0 0"/>
        <mass value="0.001"/>
        <inertia ixx="0.0000167" ixy="0" ixz="0" iyy="0.0000167" iyz="0" izz="0.0000167"/>
    </inertial>
  </link>
  <joint name="px" type="prismatic">
    <parent link="px_link"/>
    <child link="py_link"/>
    <limit effort="1000" velocity="1000"/>
    <axis xyz="1 0 0"/>
    <origin rpy="0 0 0" xyz="0 0 0"/>
  </joint>

  <link name="py_link">
    <inertial>
        <origin rpy="0 0 0" xyz="0 0 0"/>
        <mass value="0.001"/>
        <inertia ixx="0.0000167" ixy="0" ixz="0" iyy="0.0000167" iyz="0" izz="0.0000167"/>
    </inertial>
  </link>
  <joint name="py" type="prismatic">
    <parent link="py_link"/>
    <child link="pz_link"/>
    <limit effort="1000" velocity="1000"/>
    <axis xyz="0 1 0"/>
    <origin rpy="0 0 0" xyz="0 0 0"/>
  </joint>

  <link name="pz_link">
    <inertial>
        <origin rpy="0 0 0" xyz="0 0 0"/>
        <mass value="0.001"/>
        <inertia ixx="0.0000167" ixy="0" ixz="0" iyy="0.0000167" iyz="0" izz="0.0000167"/>
    </inertial>
  </link>
  <joint name="pz" type="prismatic">
    <parent link="pz_link"/>
    <child link="ax_link"/>
    <limit effort="1000" velocity="1000"/>
    <axis xyz="0 0 1"/>
    <origin rpy="0 0 0" xyz="0 0 0"/>
  </joint>

  <link name="ax_link">
    <inertial>
        <origin rpy="0 0 0" xyz="0 0 0"/>
        <mass value="0.001"/>
        <inertia ixx="0.0000167" ixy="0" ixz="0" iyy="0.0000167" iyz="0" izz="0.0000167"/>
    </inertial>
  </link>
  <joint name="ax" type="revolute">
    <parent link="ax_link"/>
    <child link="ay_link"/>
    <limit effort="1000" velocity="1000"/>
    <axis xyz="1 0 0"/>
    <origin rpy="0 0 0" xyz="0 0 0"/>
  </joint>

  <link name="ay_link">
    <inertial>
        <origin rpy="0 0 0" xyz="0 0 0"/>
        <mass value="0.001"/>
        <inertia ixx="0.0000167" ixy="0" ixz="0" iyy="0.0000167" iyz="0" izz="0.0000167"/>
    </inertial>
  </link>
  <joint name="ay" type="revolute">
    <parent link="ay_link"/>
    <child link="az_link"/>
    <limit effort="1000" velocity="1000"/>
    <axis xyz="0 1 0"/>
    <origin rpy="0 0 0" xyz="0 0 0"/>
  </joint>

    <link name="az_link">
    <inertial>
        <origin rpy="0 0 0" xyz="0 0 0"/>
        <mass value="0.001"/>
        <inertia ixx="0.0000167" ixy="0" ixz="0" iyy="0.0000167" iyz="0" izz="0.0000167"/>
    </inertial>
  </link>
  <joint name="az" type="revolute">
    <parent link="az_link"/>
    <child link="cube_link"/>
    <limit effort="1000" velocity="1000"/>
    <axis xyz="0 0 1"/>
    <origin rpy="0 0 0" xyz="0 0 0"/>
  </joint>

  <link name="cube_link">
    <contact>
        <lateral_friction value="1"/>
    </contact>
    <collision>
        <geometry>
            <box size="0.1 0.1 0.1"/>
        </geometry>
    </collision>
    <inertial>
        <origin rpy="0 0 0" xyz="0 0 0"/>
        <mass value="1.0"/>
        <inertia ixx="0.00167" ixy="0" ixz="0" iyy="0.00167" iyz="0" izz="0.00167"/>
      </inertial>
    <visual>
        <origin rpy="0 0 0" xyz="0 0 0"/>
        <geometry>
          <box size="0.1 0.1 0.1"/>
        </geometry>
        <material name="green">
          <color rgba="1 1 1 1"/>
        </material>
    </visual>
  </link>
</robot>