<mujoco model="solo">
  <compiler angle="radian" meshdir="../meshes/solo12/"/>
  <statistic meansize="0.0982686" extent="0.608773" center="0 2.74191e-05 -0.0510751"/>
  <asset>
    <mesh name="solo_12_base" file="solo_12_base.stl"/>
    <mesh name="solo12_hip_fe_fl" file="solo12_hip_fe_fl.stl"/>
    <mesh name="solo_upper_leg_left_side" file="solo_upper_leg_left_side.stl"/>
    <mesh name="solo_lower_leg_v2_left_side" file="solo_lower_leg_v2_left_side.stl"/>
    <mesh name="solo12_hip_fe_fr" file="solo12_hip_fe_fr.stl"/>
    <mesh name="solo_upper_leg_right_side" file="solo_upper_leg_right_side.stl"/>
    <mesh name="solo_lower_leg_v2_right_side" file="solo_lower_leg_v2_right_side.stl"/>
    <mesh name="solo12_hip_fe_hl" file="solo12_hip_fe_hl.stl"/>
    <mesh name="solo12_hip_fe_hr" file="solo12_hip_fe_hr.stl"/>
    <texture type="skybox" builtin="gradient" rgb1="0.3 0.5 0.7" rgb2="0 0 0" width="512" height="3072"/>
    <texture type="2d" name="groundplane" builtin="checker" mark="edge" rgb1="0.2 0.3 0.4" rgb2="0.1 0.2 0.3"
      markrgb="0.8 0.8 0.8" width="300" height="300"/>
    <material name="groundplane" texture="groundplane" texuniform="true" texrepeat="5 5" reflectance="0.2"/>
  </asset>
  <worldbody>
    <light pos="1 0 1.5" dir="0 0 -1" directional="true"/>
    <light pos="-1 0 1.5" dir="0 0 -1" directional="true"/>
    <geom name="floor" size="0 0 0.05" type="plane" material="groundplane"/>
    <body name="base_link" pos="0 0 0.4">
      <inertial pos="-0.00082966 1.05e-06 -0.0006021" quat="-0.00116678 0.706653 0.00115432 0.707559" mass="1.25124" diaginertia="0.0160537 0.0138852 0.00266206"/>
      <geom type="mesh" rgba="0.8 0.8 0.8 1" mesh="solo_12_base" contype="0" conaffinity="5"/>
      <freejoint/>
      <body name="FL_SHOULDER" pos="0.2141 0.0875 0">
        <inertial pos="-0.0940725 -0.00438935 1.384e-05" quat="0.525393 0.524526 0.474075 0.473379" mass="0.14196" diaginertia="0.000386433 0.0003805 2.42272e-05"/>
        <joint name="FL_HAA" pos="0 0 0" axis="1 0 0" range="-10 10"/>
        <geom pos="0.0195 0 0" type="mesh" rgba="0.8 0.8 0.8 1" mesh="solo12_hip_fe_fl" contype="0" conaffinity="5"/>
        <body name="FL_UPPER_LEG" pos="-0.0195 0.014 0">
          <inertial pos="1.53e-05 0.0176764 -0.0783823" quat="0.705254 -0.0412383 0.0411345 0.706558" mass="0.147373" diaginertia="0.000421743 0.0004154 2.44467e-05"/>
          <joint name="FL_HFE" pos="0 0 0" axis="0 1 0" range="-10 10"/>
          <geom type="mesh" rgba="0.8 0.8 0.8 1" mesh="solo_upper_leg_left_side" contype="0" conaffinity="5"/>
          <body name="FL_LOWER_LEG" pos="0 0.03745 -0.16">
            <inertial pos="0 0.00776716 -0.0700388" quat="0.707057 -0.00837059 0.00837059 0.707057" mass="0.0231829" diaginertia="8.58474e-05 8.508e-05 1.34264e-06"/>
            <joint name="FL_KFE" pos="0 0 0" axis="0 1 0" range="-10 10"/>
            <geom type="mesh" rgba="0.8 0.8 0.8 1" mesh="solo_lower_leg_v2_left_side" contype="0" conaffinity="5"/>
            <body name="FL_FOOT" pos="0 0.009 -0.16">
              <inertial pos="0 0 0" mass="0" diaginertia="0 0 0"/>
            </body>
          </body>
        </body>
      </body>
      <body name="FR_SHOULDER" pos="0.2141 -0.0875 0">
        <inertial pos="-0.0940725 0.00438935 -1.384e-05" quat="0.474075 0.473379 0.525393 0.524526" mass="0.14196" diaginertia="0.000386433 0.0003805 2.42272e-05"/>
        <joint name="FR_HAA" pos="0 0 0" axis="1 0 0" range="-10 10"/>
        <geom pos="0.0195 0 0" type="mesh" rgba="0.8 0.8 0.8 1" mesh="solo12_hip_fe_fr" contype="0" conaffinity="5"/>
        <body name="FR_UPPER_LEG" pos="-0.0195 -0.014 0">
          <inertial pos="-1.53e-05 -0.0176764 -0.0783823" quat="0.705254 0.0412383 -0.0411345 0.706558" mass="0.147373" diaginertia="0.000421743 0.0004154 2.44467e-05"/>
          <joint name="FR_HFE" pos="0 0 0" axis="0 1 0" range="-10 10"/>
          <geom type="mesh" rgba="0.8 0.8 0.8 1" mesh="solo_upper_leg_right_side" contype="0" conaffinity="5"/>
          <body name="FR_LOWER_LEG" pos="0 -0.03745 -0.16">
            <inertial pos="0 -0.00776716 -0.0700388" quat="0.707057 0.00837059 -0.00837059 0.707057" mass="0.0231829" diaginertia="8.58474e-05 8.508e-05 1.34264e-06"/>
            <joint name="FR_KFE" pos="0 0 0" axis="0 1 0" range="-10 10"/>
            <geom type="mesh" rgba="0.8 0.8 0.8 1" mesh="solo_lower_leg_v2_right_side" contype="0" conaffinity="5"/>
            <body name="FR_FOOT" pos="0 -0.009 -0.16">
              <inertial pos="0 0 0" mass="0" diaginertia="0 0 0"/>
            </body>
          </body>
        </body>
      </body>
      <body name="HL_SHOULDER" pos="-0.2141 0.0875 0">
        <inertial pos="0.0940725 -0.00438935 -1.384e-05" quat="0.473379 0.474075 0.524526 0.525393" mass="0.14196" diaginertia="0.000386433 0.0003805 2.42272e-05"/>
        <joint name="HL_HAA" pos="0 0 0" axis="1 0 0" range="-10 10"/>
        <geom pos="-0.0195 0 0" type="mesh" rgba="0.8 0.8 0.8 1" mesh="solo12_hip_fe_hl" contype="0" conaffinity="5"/>
        <body name="HL_UPPER_LEG" pos="0.0195 0.014 0">
          <inertial pos="1.53e-05 0.0176764 -0.0783823" quat="0.705254 -0.0412383 0.0411345 0.706558" mass="0.147373" diaginertia="0.000421743 0.0004154 2.44467e-05"/>
          <joint name="HL_HFE" pos="0 0 0" axis="0 1 0" range="-10 10"/>
          <geom type="mesh" rgba="0.8 0.8 0.8 1" mesh="solo_upper_leg_left_side" contype="0" conaffinity="5"/>
          <body name="HL_LOWER_LEG" pos="0 0.03745 -0.16">
            <inertial pos="0 0.00776716 -0.0700388" quat="0.707057 -0.00837059 0.00837059 0.707057" mass="0.0231829" diaginertia="8.58474e-05 8.508e-05 1.34264e-06"/>
            <joint name="HL_KFE" pos="0 0 0" axis="0 1 0" range="-10 10"/>
            <geom type="mesh" rgba="0.8 0.8 0.8 1" mesh="solo_lower_leg_v2_left_side" contype="0" conaffinity="5"/>
            <body name="HL_FOOT" pos="0 0.009 -0.16">
              <inertial pos="0 0 0" mass="0" diaginertia="0 0 0"/>
            </body>
          </body>
        </body>
      </body>
      <body name="HR_SHOULDER" pos="-0.2141 -0.0875 0">
        <inertial pos="0.0940725 0.00438935 1.384e-05" quat="0.524526 0.525393 0.473379 0.474075" mass="0.14196" diaginertia="0.000386433 0.0003805 2.42272e-05"/>
        <joint name="HR_HAA" pos="0 0 0" axis="1 0 0" range="-10 10"/>
        <geom pos="-0.0195 0 0" type="mesh" rgba="0.8 0.8 0.8 1" mesh="solo12_hip_fe_hr" contype="0" conaffinity="5"/>
        <body name="HR_UPPER_LEG" pos="0.0195 -0.014 0">
          <inertial pos="-1.53e-05 -0.0176764 -0.0783823" quat="0.705254 0.0412383 -0.0411345 0.706558" mass="0.147373" diaginertia="0.000421743 0.0004154 2.44467e-05"/>
          <joint name="HR_HFE" pos="0 0 0" axis="0 1 0" range="-10 10"/>
          <geom type="mesh" rgba="0.8 0.8 0.8 1" mesh="solo_upper_leg_right_side" contype="0" conaffinity="5"/>
          <body name="HR_LOWER_LEG" pos="0 -0.03745 -0.16">
            <inertial pos="0 -0.00776716 -0.0700388" quat="0.707057 0.00837059 -0.00837059 0.707057" mass="0.0231829" diaginertia="8.58474e-05 8.508e-05 1.34264e-06"/>
            <joint name="HR_KFE" pos="0 0 0" axis="0 1 0" range="-10 10"/>
            <geom type="mesh" rgba="0.8 0.8 0.8 1" mesh="solo_lower_leg_v2_right_side" contype="0" conaffinity="5" />
            <body name="HR_FOOT" pos="0 -0.009 -0.16">
              <inertial pos="0 0 0" mass="0" diaginertia="0 0 0"/>
            </body>
          </body>
        </body>
      </body>
    </body>
  </worldbody>
  <actuator>
    <motor name="FL_HAA" joint="FL_HAA" ctrlrange="-4 4"/>
    <motor name="FL_HFE" joint="FL_HFE" ctrlrange="-4 4"/>
    <motor name="FL_KFE" joint="FL_KFE" ctrlrange="-4 4"/>
    <motor name="FR_HAA" joint="FR_HAA" ctrlrange="-4 4"/>
    <motor name="FR_HFE" joint="FR_HFE" ctrlrange="-4 4"/>
    <motor name="FR_KFE" joint="FR_KFE" ctrlrange="-4 4"/>
    <motor name="HL_HAA" joint="HL_HAA" ctrlrange="-4 4"/>
    <motor name="HL_HFE" joint="HL_HFE" ctrlrange="-4 4"/>
    <motor name="HL_KFE" joint="HL_KFE" ctrlrange="-4 4"/>
    <motor name="HR_HAA" joint="HR_HAA" ctrlrange="-4 4"/>
    <motor name="HR_HFE" joint="HR_HFE" ctrlrange="-4 4"/>
    <motor name="HR_KFE" joint="HR_KFE" ctrlrange="-4 4"/>
  </actuator>
</mujoco>
